Workbook

Sheet Sheet1
A1: Sorterings ID | B1: Data type | C1: Navn DE/ENG | D1: Navn DK | E1: UUID | F1: Global Opvarmning, modul A1-A3 | G1: Global Opvarmning, modul C3 | H1: Global Opvarmning, modul C4 | I1: Global Opvarmning, modul D | J1: Deklareret faktor (FU) | K1: Deklareret enhed (FU) | L1: Masse faktor | M1: Masse enhed | N1: Url (link) | O1: Kommentar
A2: #G0149 | B2: Generisk data | C2: Kunstharzestrich | D2: Afretningslag, hårdeplast | E2: =VLOOKUP(Table1[[#This Row],[Navn DK]],product_nodes_new_id!A:B,2,FALSE) -> cb07a54a-f9aa-5139-840b-03db8db822e5 | F2: 0.31541417 | G2: 0 | H2: 0.017601035 | I2: 0 | J2: 1 | K2: kg | L2: 1800 | M2: kg/m³ | N2: https://www.oekobaudat.de/OEKOBAU.DAT/resource/processes/8f060568-aca6-4375-86f4-340b806962c4?version=20.23.050
A3: #G1057 | B3: Generisk data | C3: Klimagerät (direktverdampfer) (pro 1 kw) | D3: Aircondition (direkte fordamper) (per 1 kW) | E3: =VLOOKUP(Table1[[#This Row],[Navn DK]],product_nodes_new_id!A:B,2,FALSE) -> 4e027c0a-b06c-5003-ae4a-cc13b31f4ef9 | F3: 45.504058 | G3: 2.9339393 | H3: 0.5122522 | I3: -19.228392 | J3: 1 | K3: stk | L3: 13.4 | M3: kg/stk. | N3: https://www.oekobaudat.de/OEKOBAU.DAT/resource/processes/9da0974d-cd0c-402f-a72e-ee07f2da68d6?version=20.23.050
A4: #G0956 | B4: Generisk data | C4: Gussteile aus aluminium | D4: Aluminium, støbegods | E4: =VLOOKUP(Table1[[#This Row],[Navn DK]],product_nodes_new_id!A:B,2,FALSE) -> 105a2244-c406-5ac7-8695-d1e2b2ed0e8f | F4: 11.009422 | G4: 0 | H4: 0 | I4: -7.2765834 | J4: 1 | K4: kg | L4: 2700 | M4: kg/m³ | N4: https://www.oekobaudat.de/OEKOBAU.DAT/resource/processes/568f2c96-2d04-43ff-bf03-8e48de9f11ff?version=20.23.050
A5: #G0625 | B5: Generisk data | C5: Aluminiumfolie (d=0,1 mm) | D5: Aluminiumsfolie (d=0,1 mm) | E5: =VLOOKUP(Table1[[#This Row],[Navn DK]],product_nodes_new_id!A:B,2,FALSE) -> 3956c273-6549-57a3-a889-1ba0b51832e4 | F5: 3.1169807 | G5: 0 | H5: 0 | I5: -2.0374433 | J5: 1 | K5: M2 | L5: 0.28 | M5: kg/m² | N5: https://www.oekobaudat.de/OEKOBAU.DAT/resource/processes/0fdc2fd3-fe48-499f-9158-74a6cc7185dc?version=20.23.050
A6: #G0452 | B6: Generisk data | C6: Aluminiumblech | D6: Aluminiumsplade | E6: =VLOOKUP(Table1[[#This Row],[Navn DK]],product_nodes_new_id!A:B,2,FALSE) -> a1dbf112-7b04-5e88-9bf8-380a14e48f84 | F6: 10.534353 | G6: 0 | H6: 0 | I6: -7.2765834 | J6: 1 | K6: kg | L6: 2700 | M6: kg/m³ | N6: https://www.oekobaudat.de/OEKOBAU.DAT/resource/processes/f0f13788-bc1b-44d4-9f37-082a6d22b432?version=20.23.050
A7: #G0333 | B7: Generisk data | C7: Aluminium Profil | D7: Aluminiumsprofil | E7: =VLOOKUP(Table1[[#This Row],[Navn DK]],product_nodes_new_id!A:B,2,FALSE) -> f181bb37-59db-5203-897e-b3b4da47173d | F7: 10.697766 | G7: 0 | H7: 0 | I7: -7.2765834 | J7: 1 | K7: kg | L7: 2700 | M7: kg/m³ | N7: https://www.oekobaudat.de/OEKOBAU.DAT/resource/processes/fdc99ab8-d843-44ec-a66c-92367d244321?version=20.23.050
A8: #G0484 | B8: Generisk data | C8: Ammoniak (r717) | D8: Ammoniak (R717) | E8: =VLOOKUP(Table1[[#This Row],[Navn DK]],product_nodes_new_id!A:B,2,FALSE) -> 8dd8910c-0a03-557f-b4d2-7b9ed709ce72 | F8: 2.5299277 | G8: 0 | H8: 0 | I8: -2.0960171 | J8: 1 | K8: kg | L8: 1 | M8: kg/kg | N8: https://www.oekobaudat.de/OEKOBAU.DAT/resource/processes/2b3bf368-34e6-4e7c-917e-6f455d4c4bb8?version=20.23.050
A9: #G0558 | B9: Generisk data | C9: Asphalttragschicht | D9: Asfalt, bærelag | E9: =VLOOKUP(Table1[[#This Row],[Navn DK]],product_nodes_new_id!A:B,2,FALSE) -> fff4fb8e-9d9a-53fc-be3a-2573ad3321a1 | F9: 0.073316331 | G9: 0 | H9: 0 | I9: -0.017009508 | J9: 1 | K9: kg | L9: 2350 | M9: kg/m³ | N9: https://www.oekobaudat.de/OEKOBAU.DAT/resource/processes/f34786e7-0953-4085-9f3d-955481cdd4ea?version=20.23.050
A10: #G0392 | B10: Generisk data | C10: Fenster-beschlag für drehkippfenster (aluminium) | D10: Beslag til dreje-kip vinduer (aluminium) | E10: =VLOOKUP(Table1[[#This Row],[Navn DK]],product_nodes_new_id!A:B,2,FALSE) -> 6e60c01d-bb86-5504-9dbd-b2963095e119 | F10: 13.750138 | G10: 0 | H10: 0 | I10: -7.6756278 | J10: 1 | K10: stk | L10: 1.65 | M10: kg/stk. | N10: https://www.oekobaudat.de/OEKOBAU.DAT/resource/processes/8dc96f29-ec8d-43ba-ba08-a2362003078a?version=20.23.050
A11: #G0644 | B11: Generisk data | C11: Fenster-beschlag für vertikales schiebefenster | D11: Beslag til lodrette skydevinduer | E11: =VLOOKUP(Table1[[#This Row],[Navn DK]],product_nodes_new_id!A:B,2,FALSE) -> 2ac87707-ca69-5b6d-86e8-d230a8bc3816 | F11: 11.880487 | G11: 0 | H11: 0 | I11: -5.6488242 | J11: 1 | K11: stk | L11: 0.932 | M11: kg/stk. | N11: https://www.oekobaudat.de/OEKOBAU.DAT/resource/processes/67331443-825b-4e74-87bb-27d5a55dd159?version=20.23.050
A12: #G1071 | B12: Generisk data | C12: Fenster-beschlag für horizontales schiebefenster | D12: Beslag til vandrette skydevinduer | E12: =VLOOKUP(Table1[[#This Row],[Navn DK]],product_nodes_new_id!A:B,2,FALSE) -> 451fa084-4d91-5678-88d4-08d7e9ee210a | F12: 6.1409319 | G12: 0 | H12: 0 | I12: -3.4283594 | J12: 1 | K12: stk | L12: 0.696 | M12: kg/stk. | N12: https://www.oekobaudat.de/OEKOBAU.DAT/resource/processes/640ca097-4329-47d0-a762-7ed858239c3a?version=20.23.050
A13: #G0147 | B13: Generisk data | C13: Beschlagverbund fenster stahl | D13: Beslag, stålvindue | E13: =VLOOKUP(Table1[[#This Row],[Navn DK]],product_nodes_new_id!A:B,2,FALSE) -> c5939aa5-cffa-5b48-8a15-1596965255fb | F13: 9.6760782 | G13: 0 | H13: 0 | I13: -4.794823 | J13: 1 | K13: stk | L13: 2.63 | M13: kg/stk. | N13: https://www.oekobaudat.de/OEKOBAU.DAT/resource/processes/b6e9b76b-5be6-4b7b-be40-c32da896190f?version=20.23.050
A14: #B1385 | B14: Branche data | C14: - | D14: Beton vægelementer, 15 cm tyk væg med 5-15 kg armering (11% udsparinger) | E14: 02d2f058-cfed-4732-8730-e212bb8e7d5f | F14: 53.1 | G14: 0.965 | H14: 0.7 | I14: -0.787 | J14: 1 | K14: M2 | L14: 320.9 | M14: kg/m² | N14: https://www.epddanmark.dk/media/oq0dzm1j/md-20015-da_rev1-betonelement-foreningen.pdf
A15: #B1393 | B15: Branche data | C15: - | D15: Beton vægelementer, 20 cm tyk væg med 16-25 kg armering (11% udsparinger) | E15: 97e29fb3-c8c3-57bf-a8b1-d823af2a3256 | F15: 73.2 | G15: 1.29 | H15: 0.932 | I15: -1.08 | J15: 1 | K15: M2 | L15: 433.9 | M15: kg/m² | N15: https://www.epddanmark.dk/media/oq0dzm1j/md-20015-da_rev1-betonelement-foreningen.pdf
A16: #B1389 | B16: Branche data | C16: - | D16: Beton vægelementer, 20 cm tyk væg med 5-15 kg armering (11% udsparinger) | E16: 69a15ad7-3ede-40b9-8640-e406917c0e45 | F16: 66.9 | G16: 1.28 | H16: 0.93 | I16: -1.01 | J16: 1 | K16: M2 | L16: 426.4 | M16: kg/m² | N16: https://www.epddanmark.dk/media/oq0dzm1j/md-20015-da_rev1-betonelement-foreningen.pdf
A17: #G0330 | B17: Generisk data | C17: Beton-mauersteine | D17: Betonmursten | E17: =VLOOKUP(Table1[[#This Row],[Navn DK]],product_nodes_new_id!A:B,2,FALSE) -> 4d5b5fc5-3a7f-5e7e-82f2-750440ed1f52 | F17: 228.2614 | G17: 13.531849 | H17: 0 | I17: -3.1492393 | J17: 1 | K17: M3 | L17: 2000 | M17: kg/m³ | N17: https://www.oekobaudat.de/OEKOBAU.DAT/resource/processes/47583aa9-56d9-4b39-8cc3-e3513210dd17?version=20.23.050
A18: #G0740 | B18: Generisk data | C18: Betonrohr, bewehrt | D18: Betonrør, armeret | E18: =VLOOKUP(Table1[[#This Row],[Navn DK]],product_nodes_new_id!A:B,2,FALSE) -> 718eca41-b0e2-596b-9ff7-292e5f46c9e8 | F18: 0.13260791 | G18: 0.0072729541 | H18: 0 | I18: -0.0014199949 | J18: 1 | K18: kg | L18: 2400 | M18: kg/m³ | N18: https://www.oekobaudat.de/OEKOBAU.DAT/resource/processes/16e0f5b5-8090-4466-b303-7b8ae71110d8?version=20.23.050
A19: #D1614 | B19: Dansk generisk data | C19: - | D19: Betonrør, u-armeret | E19: =VLOOKUP(Table1[[#This Row],[Navn DK]],product_nodes_new_id!A:B,2,FALSE) -> 5f53f099-bee7-5478-ad3a-cb455d5c8c02 | F19: 141.9 | G19: 3.7103813 | H19: 2.7441362 | I19: -1.1926226 | J19: 1 | K19: m | L19: 696 | M19: kg/m | N19: https://vbn.aau.dk/da/publications/udvikling-af-dansk-generisk-lca-data?
A20: #G1003 | B20: Generisk data | C20: Betonrohr, unbewehrt | D20: Betonrør, u-armeret | E20: =VLOOKUP(Table1[[#This Row],[Navn DK]],product_nodes_new_id!A:B,2,FALSE) -> 5f53f099-bee7-5478-ad3a-cb455d5c8c02 | F20: 0.12447531 | G20: 0.0073919647 | H20: 0 | I20: -0.0014432309 | J20: 1 | K20: kg | L20: 2400 | M20: kg/m³ | N20: https://www.oekobaudat.de/OEKOBAU.DAT/resource/processes/f421344b-6738-4e4a-82f3-10415fa9fc54?version=20.23.050
A21: #G0420 | B21: Generisk data | C21: Betonfertigteil treppe (1,1 m breite, 9 stufen a 16 cm) | D21: Betontrappe, etagehøj | E21: =VLOOKUP(Table1[[#This Row],[Navn DK]],product_nodes_new_id!A:B,2,FALSE) -> b8e2846d-3535-5de5-b915-bddbce5257cd | F21: 265.02546 | G21: 14.045879 | H21: 0 | I21: -2.7423624 | J21: 1 | K21: stk | L21: 1965 | M21: kg/stk. | N21: https://www.oekobaudat.de/OEKOBAU.DAT/resource/processes/2632f4e8-7671-4d87-a8bc-9defdb54d117?version=20.23.050
A22: #G0673 | B22: Generisk data | C22: Asphaltbinder | D22: Bindelag | E22: =VLOOKUP(Table1[[#This Row],[Navn DK]],product_nodes_new_id!A:B,2,FALSE) -> 59d2774b-9829-581f-aee2-54f589203c36 | F22: 0.08120417 | G22: 0 | H22: 0 | I22: -0.017009508 | J22: 1 | K22: kg | L22: 210 | M22: kg/m² | N22: https://www.oekobaudat.de/OEKOBAU.DAT/resource/processes/3d1b480d-243f-4ff2-aa16-428e1a93f5d8?version=20.23.050
A23: #G0439 | B23: Generisk data | C23: Bitumen emulsion (40% bitumen, 60% wasser) | D23: Bitumenemulsion (40% bitumen, 60% vand) | E23: =VLOOKUP(Table1[[#This Row],[Navn DK]],product_nodes_new_id!A:B,2,FALSE) -> 9b6ad11e-fbad-5583-bb4d-4cd56572fcf1 | F23: 0.35629369 | G23: 0 | H23: 0.091400858 | I23: 0 | J23: 1 | K23: kg | L23: 1 | M23: kg/kg | N23: https://www.oekobaudat.de/OEKOBAU.DAT/resource/processes/49a70830-f0ff-4e1b-a0b7-4f4da313fa28?version=20.23.050
A24: #G0734 | B24: Generisk data | C24: Bitumen kaltkleber (60% bitumen, 23%lm, 17% wasser) | D24: Bitumenklæber | E24: =VLOOKUP(Table1[[#This Row],[Navn DK]],product_nodes_new_id!A:B,2,FALSE) -> 7ee18f05-d80d-5626-911f-ecfa7ca9a6e9 | F24: 0.66778125 | G24: 0 | H24: 0.091400858 | I24: 0 | J24: 1 | K24: kg | L24: 1 | M24: kg/kg | N24: https://www.oekobaudat.de/OEKOBAU.DAT/resource/processes/57a01f9b-798f-4a5d-b476-bd20c7bd25bd?version=20.23.050
A25: #G0235 | B25: Generisk data | C25: Bleibleche | D25: Blyplader | E25: =VLOOKUP(Table1[[#This Row],[Navn DK]],product_nodes_new_id!A:B,2,FALSE) -> 5a1ad173-c2e0-5684-8fd4-e520f10dc9e5 | F25: 1.2516171 | G25: 0 | H25: 0 | I25: 1.584745 | J25: 1 | K25: kg | L25: 11342 | M25: kg/m³ | N25: https://www.oekobaudat.de/OEKOBAU.DAT/resource/processes/43312667-1727-4f43-b8ad-fe82268b7691?version=20.23.050
A26: #G0951 | B26: Generisk data | C26: Baumwolle konventionell | D26: Bomuld | E26: =VLOOKUP(Table1[[#This Row],[Navn DK]],product_nodes_new_id!A:B,2,FALSE) -> b6c8f648-e7bc-5660-8e3d-c038ed2219a4 | F26: -0.62842243 | G26: 1.7573318 | H26: 0 | I26: -0.49287905 | J26: 1 | K26: kg | L26: 1 | M26: kg/kg | N26: https://www.oekobaudat.de/OEKOBAU.DAT/resource/processes/5747cdb6-fb7d-4fbf-b7ee-38647ee470c7?version=20.23.050
A27: #G1051 | B27: Generisk data | C27: Baumwolle ökologisch | D27: Bomuld, økologisk | E27: =VLOOKUP(Table1[[#This Row],[Navn DK]],product_nodes_new_id!A:B,2,FALSE) -> aa20b800-8258-5354-9777-5311585f8ca6 | F27: -0.21224089 | G27: 1.7573318 | H27: 0 | I27: -0.49287905 | J27: 1 | K27: kg | L27: 1 | M27: kg/kg | N27: https://www.oekobaudat.de/OEKOBAU.DAT/resource/processes/e4800e06-854a-4f09-9114-21340fd19af5?version=20.23.050
A28: #G0782 | B28: Generisk data | C28: Trinkwasserrohr pe-x-alu | D28: Brugsvandsrør, Alu-PEX | E28: =VLOOKUP(Table1[[#This Row],[Navn DK]],product_nodes_new_id!A:B,2,FALSE) -> 09bc1b03-18ed-5976-b91e-68a54c3e5f0a | F28: 7.5838013 | G28: 1.8830718 | H28: 0 | I28: -3.9902456 | J28: 1 | K28: kg | L28: 1 | M28: kg/kg | N28: https://www.oekobaudat.de/OEKOBAU.DAT/resource/processes/c9d466d3-d5cb-4be6-9ae3-609212c4438a?version=20.23.050
... A36: #G0085 | B36: Generisk data | C36: Foamglas® t4+ | D36: Celleglas-isolering 115 kg/m³ | E36: =VLOOKUP(Table1[[#This Row],[Navn DK]],product_nodes_new_id!A:B,2,FALSE) -> e662f0b8-9a21-57ca-8e98-642d3dc20436 | F36: 1.43 | G36: 0.00241 | H36: 0.0153 | I36: -0.1773 | J36: 1 | K36: kg | L36: 115 | M36: kg/m³ | N36: https://oekobaudat.de/OEKOBAU.DAT/resource/datastocks/c391de0f-2cfd-47ea-8883-c661d294e2ba/processes/c93da4c3-94c9-4c86-b092-610cf1cf012f?format=html&lang=en&version=00.10.000
A37: #D1571 | B37: Dansk generisk data | C37: - | D37: Cement 42,5 MPa | E37: f06a7760-719a-5504-9278-eeb2bc1ff567 | F37: 1017.5 | G37: 0 | H37: 0 | I37: 0 | J37: 1 | K37: ton | L37: 3100 | M37: kg/m³ | N37: https://vbn.aau.dk/da/publications/udvikling-af-dansk-generisk-lca-data?
A38: #D1572 | B38: Dansk generisk data | C38: - | D38: Cement 52,5 MPa | E38: aa834931-e3d7-502d-8cb4-4c5eb112ff28 | F38: 1144 | G38: 0 | H38: 0 | I38: 0 | J38: 1 | K38: ton | L38: 3100 | M38: kg/m³ | N38: https://vbn.aau.dk/da/publications/udvikling-af-dansk-generisk-lca-data?
A39: #G0457 | B39: Generisk data | C39: Zementgebundene spanplatte (generisch) | D39: Cementbundet spånplade | E39: =VLOOKUP(Table1[[#This Row],[Navn DK]],product_nodes_new_id!A:B,2,FALSE) -> d762565c-224a-5689-a76b-0ae8b18a50aa | F39: 1721.4498 | G39: 233.13469 | H39: 0 | I39: -64.95747 | J39: 1 | K39: M3 | L39: 1200 | M39: kg/m³ | N39: https://www.oekobaudat.de/OEKOBAU.DAT/resource/processes/c772eb77-7b60-4b1f-8b5b-0be23e26549a?version=20.23.050
A40: #G0466 | B40: Generisk data | C40: Umwälzpumpe 250-1000w | D40: Cirkulationspumpe 250-1000 W | E40: =VLOOKUP(Table1[[#This Row],[Navn DK]],product_nodes_new_id!A:B,2,FALSE) -> 08e14bb3-573d-5255-adc9-4bf230556711 | F40: 124.43216 | G40: 4.2647457 | H40: 0.30354955 | I40: -20.398002 | J40: 1 | K40: stk | L40: 24.7 | M40: kg/stk. | N40: https://www.oekobaudat.de/OEKOBAU.DAT/resource/processes/5b5ed926-7052-48d3-a6b8-9039c04f5036?version=20.23.050
A41: #G0372 | B41: Generisk data | C41: Umwälzpumpe 50-250w | D41: Cirkulationspumpe 50-250 W | E41: =VLOOKUP(Table1[[#This Row],[Navn DK]],product_nodes_new_id!A:B,2,FALSE) -> 3b7011ba-8153-59b6-8729-deb3114c0a44 | F41: 24.886433 | G41: 0.85294915 | H41: 0.060709911 | I41: -4.0796004 | J41: 1 | K41: stk | L41: 4.94 | M41: kg/stk. | N41: https://www.oekobaudat.de/OEKOBAU.DAT/resource/processes/700c0c68-8aec-48b8-a276-aa60a01babda?version=20.23.050
A42: #B1632 | B42: Branche data | C42: Circular ventilation ducts | D42: Ventilationskanal, galvaniseret stål | E42: =VLOOKUP(Table1[[#This Row],[Navn DK]],product_nodes_new_id!A:B,2,FALSE) -> 6099aa35-8e86-589f-a9f1-fd92a6bdbeb7 | F42: 3.82 | G42: 0.0535 | H42: 0.0012 | I42: -1.49 | J42: 1 | K42: kg | L42: 1 | M42: kg/kg | N42: https://www.epddanmark.dk/media/xvdjagkr/md-23022-en.pdf
A43: #G0946 | B43: Generisk data | C43: Cr profil (chloropren-kautschuk) | D43: CR-profil til forsejling (chloropren gummi) | E43: =VLOOKUP(Table1[[#This Row],[Navn DK]],product_nodes_new_id!A:B,2,FALSE) -> 0a10b816-3378-5fec-b7c2-89ff0cdf08fb | F43: 1.0555886 | G43: 0.55477392 | H43: 0 | I43: -0.19619498 | J43: 1 | K43: m | L43: 0.18 | M43: kg/m | N43: https://www.oekobaudat.de/OEKOBAU.DAT/resource/processes/2dc5d1cf-ffce-42c2-a127-f412f3ef5fe2?version=20.23.050
A44: #G0523 | B44: Generisk data | C44: Pfosten/riegel system aus aluminium mit dreifachverglasung | D44: Curtain wall facade med 3-lags ruder, aluminium | E44: =VLOOKUP(Table1[[#This Row],[Navn DK]],product_nodes_new_id!A:B,2,FALSE) -> 6d1ae546-d4e4-5408-9a60-c00fe201f9ae | F44: 119.98248 | G44: 6.2130039 | H44: 0.45059649 | I44: -33.448275 | J44: 1 | K44: M2 | L44: 16.5 | M44: kg/m² | N44: https://www.oekobaudat.de/OEKOBAU.DAT/resource/processes/4dd9a97f-6afa-4e12-a0fb-71da41d7afe4?version=20.23.050
A45: #G0111 | B45: Generisk data | C45: Pfosten/riegel system aus stahl mit dreifachverglasung | D45: Curtain wall facade med 3-lags ruder, stål | E45: =VLOOKUP(Table1[[#This Row],[Navn DK]],product_nodes_new_id!A:B,2,FALSE) -> d2cad8c6-0489-5911-a693-8c3eef18474c | F45: 95.928581 | G45: 6.2130039 | H45: 0.45059649 | I45: -13.954595 | J45: 1 | K45: M2 | L45: 21.4 | M45: kg/m² | N45: https://www.oekobaudat.de/OEKOBAU.DAT/resource/processes/77dbec35-a9ed-462f-91dc-c26fce408a2b?version=20.23.050
A46: #G0961 | B46: Generisk data | C46: Pfosten/riegel aus aluminium | D46: Curtain wall profiler, aluminium | E46: =VLOOKUP(Table1[[#This Row],[Navn DK]],product_nodes_new_id!A:B,2,FALSE) -> f0b3b24d-f691-5512-b1d2-41b76758c282 | F46: 54.66301 | G46: 3.4269035 | H46: 0 | I46: -32.480129 | J46: 1 | K46: m | L46: 5.7 | M46: kg/m | N46: https://www.oekobaudat.de/OEKOBAU.DAT/resource/processes/03329c6a-b5f2-47c8-a8db-1bd3b003857c?version=20.23.050
A47: #G0442 | B47: Generisk data | C47: Pfosten/riegelsystem aus stahl | D47: Curtain wall profiler, stål | E47: =VLOOKUP(Table1[[#This Row],[Navn DK]],product_nodes_new_id!A:B,2,FALSE) -> 9361290b-5650-5d0f-81fe-9ed2c487720c | F47: 36.147057 | G47: 3.4269035 | H47: 0 | I47: -13.7157 | J47: 1 | K47: m | L47: 9.48 | M47: kg/m | N47: https://www.oekobaudat.de/OEKOBAU.DAT/resource/processes/1121bd10-6918-441c-b18b-8264a277c919?version=20.23.050
...

Sheet product_nodes_new_id
A1: Danish name | B1: id | C1: unit
A2: 3-lags-rude | B2: 2633e48e-1e63-5765-aba6-aa6b6b683de0
A3: Afretningslag, cementbaseret | B3: e376df1c-29c6-5928-8bcc-2bfdd08bd63e
A4: Afretningslag, hårdeplast | B4: cb07a54a-f9aa-5139-840b-03db8db822e5
A5: Aircondition (direkte fordamper) (per 1 kW) | B5: 4e027c0a-b06c-5003-ae4a-cc13b31f4ef9
A6: Aluminium, støbegods | B6: 105a2244-c406-5ac7-8695-d1e2b2ed0e8f
A7: Aluminiumsfolie (d=0,1 mm) | B7: 3956c273-6549-57a3-a889-1ba0b51832e4
A8: Aluminiumsplade | B8: a1dbf112-7b04-5e88-9bf8-380a14e48f84
A9: Aluminiumsprofil | B9: f181bb37-59db-5203-897e-b3b4da47173d
A10: Ammoniak (R717) | B10: 8dd8910c-0a03-557f-b4d2-7b9ed709ce72
A11: Anhydrit mix | B11: d9b64c96-49b6-5267-8b3e-ade0e43b6f14
A12: Armeringsnet | B12: b3c6e51a-db0c-52e5-a0f1-1d416dbf5c33
A13: Asfalt, bærelag | B13: fff4fb8e-9d9a-53fc-be3a-2573ad3321a1
... A466: ​Rulleskodder, PVC | B466: aa94b285-776c-5649-8e8d-83cb96654d2d
