Workbook

Sheet Sheet1
A1: Sorterings ID | B1: Data type | C1: Navn DE/ENG | D1: Navn DK | E1: UUID | F1: Global Opvarmning, modul A1-A3 | G1: Global Opvarmning, modul C3 | H1: Global Opvarmning, modul C4 | I1: Global Opvarmning, modul D | J1: Deklareret faktor (FU) | K1: Deklareret enhed (FU) | L1: Masse faktor | M1: Masse enhed | N1: Url (link) | O1: Kommentar
A2: #G0149 | B2: Generisk data | C2: Kunstharzestrich | D2: Afretningslag, hårdt plast | E2: =VLOOKUP(Table1[[#This Row],[Navn DK]],product_nodes_new_id!A:C,3,FALSE) -> c1e386eb-042a-4b05-b29f-1f5587627613 | F2: 0.31541417 | G2: 0 | H2: 0.017601035 | I2: 0 | J2: 1 | K2: kg | L2: 1800 | M2: kg/m³ | N2: https://www.oekobaudat.de/OEKOBAU.DAT/resource/processes/8f060568-aca6-4375-86f4-340b806962c4?version=20.23.050
A3: #G1057 | B3: Generisk data | C3: Klimagerät (direktverdampfer) (pro 1 kw) | D3: Aircondition (direkte fordamper) (per 1 kW) | E3: =VLOOKUP(Table1[[#This Row],[Navn DK]],product_nodes_new_id!A:C,3,FALSE) -> 1709dfe7-3f83-4105-a169-128b869fa84b | F3: 45.504058 | G3: 2.9339393 | H3: 0.5122522 | I3: -19.228392 | J3: 1 | K3: stk | L3: 13.4 | M3: kg/stk. | N3: https://www.oekobaudat.de/OEKOBAU.DAT/resource/processes/9da0974d-cd0c-402f-a72e-ee07f2da68d6?version=20.23.050
A4: #D1525 | B4: Dansk generisk data | C4: - | D4: Akustikpanel, glasuld, tekstil, 20 mm | E4: =VLOOKUP(Table1[[#This Row],[Navn DK]],product_nodes_new_id!A:C,3,FALSE) -> 8f5be1d1-95d9-4f8b-9fa3-9892b6166451 | F4: 9.955 | G4: 0 | H4: 0.03608 | I4: -0.1809 | J4: 1 | K4: m² | L4: 154 | M4: kg/m³ | N4: https://vbn.aau.dk/da/publications/udvikling-af-dansk-generisk-lca-data?
A5: #D1526 | B5: Dansk generisk data | C5: - | D5: Akustikpanel, glasuld, tekstil, 40 mm | E5: =VLOOKUP(Table1[[#This Row],[Navn DK]],product_nodes_new_id!A:C,3,FALSE) -> a3daac12-50b5-433c-a210-109a3c3a1004 | F5: 13.2 | G5: 0 | H5: 0.03608 | I5: -0.1809 | J5: 1 | K5: m² | L5: 126 | M5: kg/m³ | N5: https://vbn.aau.dk/da/publications/udvikling-af-dansk-generisk-lca-data?
A6: #D1619 | B6: Dansk generisk data | C6: - | D6: Akustikpanel, strå | E6: =VLOOKUP(Table1[[#This Row],[Navn DK]],product_nodes_new_id!A:C,3,FALSE) -> 4e4d085f-eab6-4836-a7cc-473fb3184f32 | F6: -135.126 | G6: 453.2 | H6: 23.76 | I6: -131.4 | J6: 1 | K6: m³ | L6: 280 | M6: kg/m³ | N6: https://vbn.aau.dk/da/publications/udvikling-af-dansk-generisk-lca-data?
A7: #D1523 | B7: Dansk generisk data | C7: - | D7: Akustikpanel, træbeton, malet | E7: =VLOOKUP(Table1[[#This Row],[Navn DK]],product_nodes_new_id!A:C,3,FALSE) -> 634786fd-a36e-4ba6-8f6a-280ddee5d989 | F7: 2.1835 | G7: 0 | H7: 11 | I7: -0.4986 | J7: 1 | K7: m² | L7: 470.5 | M7: kg/m³ | N7: https://vbn.aau.dk/da/publications/udvikling-af-dansk-generisk-lca-data?
A8: #D1522 | B8: Dansk generisk data | C8: - | D8: Akustikpanel, træbeton, umalet | E8: =VLOOKUP(Table1[[#This Row],[Navn DK]],product_nodes_new_id!A:C,3,FALSE) -> a6527cf6-5b42-456b-a035-bddbea69c068 | F8: 1.65825 | G8: 0 | H8: 11.11 | I8: -0.5013 | J8: 1 | K8: m² | L8: 459.5 | M8: kg/m³ | N8: https://vbn.aau.dk/da/publications/udvikling-af-dansk-generisk-lca-data?
A9: #D1524 | B9: Dansk generisk data | C9: - | D9: Akustikpanel, trælister på filt | E9: =VLOOKUP(Table1[[#This Row],[Navn DK]],product_nodes_new_id!A:C,3,FALSE) -> 078ba92b-1e88-4fce-987d-5875b22997fc | F9: 24.937 | G9: 14.19 | H9: 0 | I9: -1.8 | J9: 1 | K9: m² | L9: 8.65 | M9: kg/m² | N9: https://vbn.aau.dk/da/publications/udvikling-af-dansk-generisk-lca-data?
A10: #D1617 | B10: Dansk generisk data | C10: - | D10: Akustikpanel, ålegræs | E10: =VLOOKUP(Table1[[#This Row],[Navn DK]],product_nodes_new_id!A:C,3,FALSE) -> 7b7d9385-cb7c-4a14-81b1-e5a046b94be4 | F10: -3.22704 | G10: 8.2896 | H10: 0 | I10: -1.52064 | J10: 1 | K10: m² | L10: 137 | M10: kg/m³ | N10: https://vbn.aau.dk/da/publications/udvikling-af-dansk-generisk-lca-data?
A11: #D1618 | B11: Dansk generisk data | C11: - | D11: Akustikpanel, ålegræs, brandhæmmende | E11: =VLOOKUP(Table1[[#This Row],[Navn DK]],product_nodes_new_id!A:C,3,FALSE) -> 56b26361-f5ab-4794-9e3b-0e273252c151 | F11: -1.57248 | G11: 7.6032 | H11: 0 | I11: -1.37376 | J11: 1 | K11: m² | L11: 137 | M11: kg/m³ | N11: https://vbn.aau.dk/da/publications/udvikling-af-dansk-generisk-lca-data?
A12: #G0956 | B12: Generisk data | C12: Gussteile aus aluminium | D12: Aluminium, støbegods | E12: =VLOOKUP(Table1[[#This Row],[Navn DK]],product_nodes_new_id!A:C,3,FALSE) -> 6c3eb5c1-e1fb-4139-aff5-1255b8ab4d86 | F12: 11.009422 | G12: 0 | H12: 0 | I12: -7.2765834 | J12: 1 | K12: kg | L12: 2700 | M12: kg/m³ | N12: https://www.oekobaudat.de/OEKOBAU.DAT/resource/processes/568f2c96-2d04-43ff-bf03-8e48de9f11ff?version=20.23.050
A13: #G0625 | B13: Generisk data | C13: Aluminiumfolie (d=0,1 mm) | D13: Aluminiumsfolie (d=0,1 mm) | E13: =VLOOKUP(Table1[[#This Row],[Navn DK]],product_nodes_new_id!A:C,3,FALSE) -> 8686d990-a212-4b00-81cd-bbe92534180c | F13: 3.1169807 | G13: 0 | H13: 0 | I13: -2.0374433 | J13: 1 | K13: m² | L13: 0.28 | M13: kg/m² | N13: https://www.oekobaudat.de/OEKOBAU.DAT/resource/processes/0fdc2fd3-fe48-499f-9158-74a6cc7185dc?version=20.23.050
... A78: #G0919 | B78: Generisk data | C78: Strom-wärmepumpe (sole-wasser, erdsonde) 20 kw | D78: El-varmepumpe (lodret jordvarme, saltvand) 20 kW | E78: =VLOOKUP(Table1[[#This Row],[Navn DK]],product_nodes_new_id!A:C,3,FALSE) -> c313a56c-9082-4b74-88e4-d60754d5dfce | F78: 1942.5485 | G78: 4.28193 | H78: 0.11906196 | I78: -128.28384 | J78: 1 | K78: stk | L78: 1498 | M78: kg/stk. | N78: https://www.oekobaudat.de/OEKOBAU.DAT/resource/processes/37ca01de-bb46-4648-a937-7ac200da6142?version=20.23.050
A79: #S0001 | B79: Standardværdi | C79: - | D79: Enfamiliehuse, afløb | E79: =VLOOKUP(Table1[[#This Row],[Navn DK]],product_nodes_new_id!A:C,3,FALSE) -> #N/A | F79: 0.008 | G79: 0.012 | H79: 0 | I79: -0.01 | L79: 0.031356308 | M79: kg/m² | N79: https://vbn.aau.dk/da/publications/klimap%C3%A5virkning-fra-nybyggeri-analytisk-grundlag-til-fastl%C3%A6ggelse?
A80: #S0002 | B80: Standardværdi | C80: - | D80: Enfamiliehuse, vand | E80: =VLOOKUP(Table1[[#This Row],[Navn DK]],product_nodes_new_id!A:C,3,FALSE) -> #N/A | F80: 0.048 | G80: 0.012 | H80: 0 | I80: -0.025 | L80: 0.29057177 | M80: kg/m² | N80: https://vbn.aau.dk/da/publications/klimap%C3%A5virkning-fra-nybyggeri-analytisk-grundlag-til-fastl%C3%A6ggelse?
A81: #S0003 | B81: Standardværdi | C81: - | D81: Enfamiliehuse, varme, ventilation og køl | E81: =VLOOKUP(Table1[[#This Row],[Navn DK]],product_nodes_new_id!A:C,3,FALSE) -> #N/A | F81: 0.475 | G81: 0.105 | H81: 0 | I81: -0.274 | L81: 3.3126424 | M81: kg/m² | N81: https://vbn.aau.dk/da/publications/klimap%C3%A5virkning-fra-nybyggeri-analytisk-grundlag-til-fastl%C3%A6ggelse?
A82: #G0181 | B82: Generisk data | C82: Epdm schaum (rohrisolierung) | D82: EPDM skum (rørisolering) | E82: =VLOOKUP(Table1[[#This Row],[Navn DK]],product_nodes_new_id!A:C,3,FALSE) -> 1d3af4fa-1a6c-4d82-a67d-5508da3ed13e | F82: 231.75146 | G82: 137.84678 | H82: 0.088510024 | I82: -47.806694 | J82: 1 | K82: m³ | L82: 55 | M82: kg/m³ | N82: https://www.oekobaudat.de/OEKOBAU.DAT/resource/processes/fb2fb3cd-df97-4077-99fd-082117ba81f6?version=20.23.050
A83: #G0680 | B83: Generisk data | C83: Epdm-dichtungen für aluminiumprofil | D83: EPDM-tætning til aluminiumsprofil | E83: =VLOOKUP(Table1[[#This Row],[Navn DK]],product_nodes_new_id!A:C,3,FALSE) -> 230fd192-0c04-4417-820b-47333b1cd7ff | F83: 0.55722887 | G83: 0.56459889 | H83: 0.56434064 | I83: -0.46772945 | J83: 1 | K83: m | L83: 0.18 | M83: kg/m | N83: https://www.oekobaudat.de/OEKOBAU.DAT/resource/processes/01a66f11-99ef-4fec-b34b-d68a377820ee?version=20.23.050
A84: #G0299 | B84: Generisk data | C84: Epdm-dichtungen aluminiumprofil, thermisch getrennt | D84: EPDM-tætning til aluminiumsprofil, med kuldebroafbrydelse | E84: =VLOOKUP(Table1[[#This Row],[Navn DK]],product_nodes_new_id!A:C,3,FALSE) -> 7f957323-e2de-4f9c-b8d3-e0635cbc9e17 | F84: 1.3311579 | G84: 1.348764 | H84: 1.3481471 | I84: -1.1173537 | J84: 1 | K84: m | L84: 0.43 | M84: kg/m | N84: https://www.oekobaudat.de/OEKOBAU.DAT/resource/processes/f0b03a7a-06f1-45c9-9597-e6c60907f3e0?version=20.23.050
A85: #D1601 | B85: Dansk generisk data | C85: - | D85: Epoxy gulvsystem | E85: =VLOOKUP(Table1[[#This Row],[Navn DK]],product_nodes_new_id!A:C,3,FALSE) -> 17aac44d-082d-49d7-8bd1-4d00422e1b82 | F85: 6.391 | G85: 0.5907 | H85: 0 | I85: -0.135 | J85: 1 | K85: kg | L85: 2.25 | M85: kg/dm³ | N85: https://vbn.aau.dk/da/publications/udvikling-af-dansk-generisk-lca-data?
A86: #D1559 | B86: Dansk generisk data | C86: - | D86: EPS isolering, grå, 30 kPa | E86: =VLOOKUP(Table1[[#This Row],[Navn DK]],product_nodes_new_id!A:C,3,FALSE) -> 3a0c6c3a-45bb-44d7-bdd2-e84afed836ab | F86: 0.8624 | G86: 1.3084 | H86: 2.3532e-05 | I86: -0.35028 | J86: 1 | K86: m² with R=1 m²K/W | L86: 11.2 | M86: kg/m³ | N86: https://vbn.aau.dk/da/publications/udvikling-af-dansk-generisk-lca-data?
A87: #D1560 | B87: Dansk generisk data | C87: - | D87: EPS isolering, grå, 60 kPa | E87: =VLOOKUP(Table1[[#This Row],[Navn DK]],product_nodes_new_id!A:C,3,FALSE) -> 8e9a9593-1278-4a0b-9c04-47f2505f2961 | F87: 1.518 | G87: 1.507 | H87: 2.7104e-05 | I87: -0.04158 | J87: 1 | K87: m² with R=1 m²K/W | L87: 12.9 | M87: kg/m³ | N87: https://vbn.aau.dk/da/publications/udvikling-af-dansk-generisk-lca-data?
A88: #D1561 | B88: Dansk generisk data | C88: - | D88: EPS isolering, grå, 80 kPa | E88: =VLOOKUP(Table1[[#This Row],[Navn DK]],product_nodes_new_id!A:C,3,FALSE) -> 19aa760f-403b-4ee0-89af-beb668edd6ff | F88: 2.42132 | G88: 1.738 | H88: 8.481e-05 | I88: -0.04599 | J88: 1 | K88: m² with R=1 m²K/W | L88: 16 | M88: kg/m³ | N88: https://vbn.aau.dk/da/publications/udvikling-af-dansk-generisk-lca-data?
A89: #D1556 | B89: Dansk generisk data | C89: - | D89: EPS isolering, hvid, 60 kPa | E89: =VLOOKUP(Table1[[#This Row],[Navn DK]],product_nodes_new_id!A:C,3,FALSE) -> 9428374e-1fe4-4554-b688-e8745feb63e4 | F89: 2.50954 | G89: 1.87 | H89: 9.108e-05 | I89: -0.08712 | J89: 1 | K89: m² with R=1 m²K/W | L89: 13.25 | M89: kg/m³ | N89: https://vbn.aau.dk/da/publications/udvikling-af-dansk-generisk-lca-data?
A90: #D1557 | B90: Dansk generisk data | C90: - | D90: EPS isolering, hvid, 80 kPa | E90: =VLOOKUP(Table1[[#This Row],[Navn DK]],product_nodes_new_id!A:C,3,FALSE) -> 96f0943e-8964-4bfa-b019-63a815402d76 | F90: 2.68235 | G90: 2.024 | H90: 9.878e-05 | I90: -0.0945 | J90: 1 | K90: m² with R=1 m²K/W | L90: 15 | M90: kg/m³ | N90: https://vbn.aau.dk/da/publications/udvikling-af-dansk-generisk-lca-data?
A91: #D1558 | B91: Dansk generisk data | C91: - | D91: EPS isolering, hvid, over 80 kPa | E91: =VLOOKUP(Table1[[#This Row],[Navn DK]],product_nodes_new_id!A:C,3,FALSE) -> 2d704b40-77ee-4051-9f91-aa602955e797 | F91: 4.560985 | G91: 6.6946 | H91: 0.0002299 | I91: -0.1062 | J91: 1 | K91: m² with R=1 m²K/W | L91: 37 | M91: kg/m³ | N91: https://vbn.aau.dk/da/publications/udvikling-af-dansk-generisk-lca-data?
A92: #S0007 | B92: Standardværdi | C92: - | D92: Etageboliger, afløb | E92: =VLOOKUP(Table1[[#This Row],[Navn DK]],product_nodes_new_id!A:C,3,FALSE) -> #N/A | F92: 0.056 | G92: 0.064 | H92: 0 | I92: -0.048 | L92: 0.46 | M92: kg/m² | N92: https://vbn.aau.dk/da/publications/klimap%C3%A5virkning-fra-nybyggeri-analytisk-grundlag-til-fastl%C3%A6ggelse?
A93: #S0008 | B93: Standardværdi | C93: - | D93: Etageboliger, vand | E93: =VLOOKUP(Table1[[#This Row],[Navn DK]],product_nodes_new_id!A:C,3,FALSE) -> #N/A | F93: 0.05 | G93: 0.01 | H93: 0 | I93: -0.02 | L93: 0.52 | M93: kg/m² | N93: https://vbn.aau.dk/da/publications/klimap%C3%A5virkning-fra-nybyggeri-analytisk-grundlag-til-fastl%C3%A6ggelse?
A94: #S0009 | B94: Standardværdi | C94: - | D94: Etageboliger,varme, ventilation og køl | E94: =VLOOKUP(Table1[[#This Row],[Navn DK]],product_nodes_new_id!A:C,3,FALSE) -> #N/A | F94: 0.394 | G94: 0.081 | H94: 0 | I94: -0.222 | L94: 3.59 | M94: kg/m² | N94: https://vbn.aau.dk/da/publications/klimap%C3%A5virkning-fra-nybyggeri-analytisk-grundlag-til-fastl%C3%A6ggelse?
A95: #G1266 | B95: Generisk data | C95: Wdvs verklebung und beschichtung leichtputz mineralisch | D95: ETICS limning og mineralsk letpuds | E95: =VLOOKUP(Table1[[#This Row],[Navn DK]],product_nodes_new_id!A:C,3,FALSE) -> 9e9e75f5-ad1e-4b5c-8e8b-5e1daae6c2e6 | F95: 4.84914 | G95: 0.132 | H95: 0.18056045 | I95: 0 | J95: 1 | K95: m² | L95: 11.4 | M95: kg/m² | N95: https://www.oekobaudat.de/OEKOBAU.DAT/resource/processes/aeb54e7e-6950-41c5-a10e-0ba3b38ea774?version=20.23.050
A96: #G1270 | B96: Generisk data | C96: Wdvs verklebung und beschichtung dekorputz mineralisch | D96: ETICS limning og mineralsk puds (Dekorputz) | E96: =VLOOKUP(Table1[[#This Row],[Navn DK]],product_nodes_new_id!A:C,3,FALSE) -> 48a4d96e-3d96-40d4-97f5-28032673d766 | F96: 7.5849222 | G96: 0.184 | H96: 0.27711684 | I96: 0 | J96: 1 | K96: m² | L96: 17.4 | M96: kg/m² | N96: https://www.oekobaudat.de/OEKOBAU.DAT/resource/processes/f873f2a7-560a-410c-97e7-dfe121134b26?version=20.23.050
A97: #G1234 | B97: Generisk data | C97: Wdvs verklebung und beschichtung kratzputz mineralisch | D97: ETICS limning og mineralsk puds (Kratzputz) | E97: =VLOOKUP(Table1[[#This Row],[Navn DK]],product_nodes_new_id!A:C,3,FALSE) -> e3310871-06f0-460e-a397-3d29184ea863 | F97: 10.108488 | G97: 0.385 | H97: 0.56607793 | I97: 0 | J97: 1 | K97: m² | L97: 35.18 | M97: kg/m² | N97: https://www.oekobaudat.de/OEKOBAU.DAT/resource/processes/8dec64ad-430f-4c96-bae1-e46814af2b70?version=20.23.050
A98: #G1287 | B98: Generisk data | C98: Wdvs verklebung und beschichtung silikonharzputz | D98: ETICS limning og silikonepuds | E98: =VLOOKUP(Table1[[#This Row],[Navn DK]],product_nodes_new_id!A:C,3,FALSE) -> aaa2f3dd-e84d-47ac-9b33-fccdc2e59c02 | F98: 5.5528861 | G98: 0 | H98: 0.20077292 | I98: 0 | J98: 1 | K98: m² | L98: 12.3 | M98: kg/m² | N98: https://www.oekobaudat.de/OEKOBAU.DAT/resource/processes/6e95743d-cdf3-4646-a6ea-f9b2bb752821?version=20.23.050
A99: #G1251 | B99: Generisk data | C99: Wdvs verklebung und beschichtung silikat-dispersionsputz | D99: ETICS-limning og belægning af silikatdispersionspuds | E99: =VLOOKUP(Table1[[#This Row],[Navn DK]],product_nodes_new_id!A:C,3,FALSE) -> 1f996148-b368-49af-8ccd-5b3d58ffae39 | F99: 5.5528861 | G99: 0 | H99: 0.20077292 | I99: 0 | J99: 1 | K99: m² | L99: 12.48 | M99: kg/m² | N99: https://www.oekobaudat.de/OEKOBAU.DAT/resource/processes/2d42602d-9913-43ed-8703-d953f7854bca?version=20.23.050
A100: #G1256 | B100: Generisk data | C100: Wdvs verklebung und beschichtung kunstharzputz | D100: ETICS-limning og belægning af syntetisk harpikspuds | E100: =VLOOKUP(Table1[[#This Row],[Navn DK]],product_nodes_new_id!A:C,3,FALSE) -> b39cc74b-0baa-4aab-85cf-141ba14b6b33 | F100: 6.540646 | G100: 0 | H100: 0.20077292 | I100: 0 | J100: 1 | K100: m² | L100: 12.48 | M100: kg/m² | N100: https://www.oekobaudat.de/OEKOBAU.DAT/resource/processes/46a05844-3fbf-47ef-889a-e7f1a4b4f825?version=20.23.050
A101: #G0327 | B101: Generisk data | C101: Eva-dachbahnen | D101: EVA-tagmembran | E101: =VLOOKUP(Table1[[#This Row],[Navn DK]],product_nodes_new_id!A:C,3,FALSE) -> cde8fc0b-16d0-455a-bf9a-d74e1ee76ea7 | F101: 5.3863566 | G101: 7.9650125 | H101: 0 | I101: -2.7684055 | J101: 1 | K101: m² | L101: 2 | M101: kg/m² | N101: https://www.oekobaudat.de/OEKOBAU.DAT/resource/processes/60203e0a-cd90-4ff9-8ec7-da3a1b0b1588?version=20.23.050
A102: #B1425 | B102: Branche data | C102: - | D102: Fabriksbeton (C20/25 SCC) i eksponeringsklasserne X0 og XC1 | E102: =VLOOKUP(Table1[[#This Row],[Navn DK]],product_nodes_new_id!A:C,3,FALSE) -> 2a4eeb06-d482-4d14-a273-25c588249278 | F102: 215 | G102: 6.94 | H102: 5.13 | I102: -4.74 | J102: 1 | K102: m³ | L102: 2212 | M102: kg/m³ | N102: https://www.epddanmark.dk/media/qoelm3vd/md-20011-da_rev1-dansk-beton-fabriksbetonforeningen.pdf
A103: #B1433 | B103: Branche data | C103: - | D103: Fabriksbeton (C25/30) i eksponeringsklasserne X0 og XC1 | E103: =VLOOKUP(Table1[[#This Row],[Navn DK]],product_nodes_new_id!A:C,3,FALSE) -> 28349df7-497b-441c-887a-13f575e90704 | F103: 241 | G103: 6.73 | H103: 4.97 | I103: -4.6 | J103: 1 | K103: m³ | L103: 2246 | M103: kg/m³ | N103: https://www.epddanmark.dk/media/qoelm3vd/md-20011-da_rev1-dansk-beton-fabriksbetonforeningen.pdf
A104: #B1477 | B104: Branche data | C104: - | D104: Fabriksbeton C30/37 | E104: =VLOOKUP(Table1[[#This Row],[Navn DK]],product_nodes_new_id!A:C,3,FALSE) -> 459ec55a-4e24-4612-8e0f-a3778eba2466 | F104: 282 | G104: 6.72 | H104: 4.97 | I104: -4.6 | J104: 1 | K104: m³ | L104: 2255 | M104: kg/m³ | N104: https://www.epddanmark.dk/media/c3alzank/md-20012-da_rev1-dansk-beton-fabriksbetonforeningen.pdf
...

Sheet product_nodes_new_id
A1: Danish name | B1: English name | C1: id | D1: unit
A2: Afretningslag, hårdt plast | B2: Tabel 7 2025: Synthetic resin screed | C2: c1e386eb-042a-4b05-b29f-1f5587627613
A3: Aircondition (direkte fordamper) (per 1 kW) | B3: Tabel 7 2025: Air conditioning system (per 1 kW) | C3: 1709dfe7-3f83-4105-a169-128b869fa84b
A4: Akustikpanel, glasuld, tekstil, 20 mm | C4: 8f5be1d1-95d9-4f8b-9fa3-9892b6166451
A5: Akustikpanel, glasuld, tekstil, 40 mm | C5: a3daac12-50b5-433c-a210-109a3c3a1004
A6: Akustikpanel, strå | C6: 4e4d085f-eab6-4836-a7cc-473fb3184f32
A7: Akustikpanel, træbeton, malet | C7: 634786fd-a36e-4ba6-8f6a-280ddee5d989
A8: Akustikpanel, træbeton, umalet | C8: a6527cf6-5b42-456b-a035-bddbea69c068
A9: Akustikpanel, trælister på filt | C9: 078ba92b-1e88-4fce-987d-5875b22997fc
A10: Akustikpanel, ålegræs | C10: 7b7d9385-cb7c-4a14-81b1-e5a046b94be4
A11: Akustikpanel, ålegræs, brandhæmmende | C11: 56b26361-f5ab-4794-9e3b-0e273252c151
A12: Aluminium, støbegods | B12: Tabel 7 2025: Aluminium die-cast parts | C12: 6c3eb5c1-e1fb-4139-aff5-1255b8ab4d86
A13: Aluminiumsfolie (d=0,1 mm) | B13: Tabel 7 2025: Aluminium foil (d=0.1 mm) | C13: 8686d990-a212-4b00-81cd-bbe92534180c
A14: Aluminiumsplade | B14: Tabel 7 2025: Aluminium sheet | C14: 013a53d1-8fed-427f-a79e-a6d21407ec3f
A15: Aluminiumsprofil | B15: Tabel 7 2025: Aluminium section | C15: 5317384e-7fc7-4334-919d-264e6e3bcf81
A16: Ammoniak (R717) | B16: Tabel 7 2025: Ammonia (R717) | C16: f32aa7b1-d35e-4fab-94af-627389e2a0de
A17: Armeringsstål | C17: f74c55e0-dfc0-4043-91de-d918dceac445
A18: Asfalt, bærelag | B18: Tabel 7 2025: Asphalt supporting layer | C18: 76244e68-5c33-44f5-bea6-78b7f836492d
A19: Bakkemørtel, kalktilpasset vådmørtel | C19: 7878f1b6-4023-4ede-a363-0fd23885d435
A20: Beslag til dreje-kip vinduer (aluminium) | B20: Tabel 7 2025: Window fitting for tilt and turn window | C20: 168e5da6-64e3-4bef-8d33-0d7327297704
A21: Beslag til lodrette skydevinduer | B21: Tabel 7 2025: Window fitting for vertical sliding window | C21: bd1de5fc-fa49-434f-aa69-20472c6323cd
A22: Beslag til vandrette skydevinduer | B22: Tabel 7 2025: Window fitting for horizontal sliding window | C22: 23538024-5254-4f94-9dd6-3c7f9d533f0c
A23: Beslag, stålvindue | B23: Tabel 7 2025: Steel window fitting | C23: 70306ada-ed43-4d16-9eeb-0e5c47f38786
A24: Beton belægningssten | C24: b83b9e7a-6dd0-4c89-bb3a-2656ba64fbbd
A25: Beton vægelementer, 15 cm tyk væg med 5-15 kg armering (11% udsparinger) | C25: 259d64ec-f220-4805-ba99-1a28116b3082
A26: Beton vægelementer, 20 cm tyk væg med 16-25 kg armering (11% udsparinger) | C26: 38f0e99c-b548-4961-8c5b-716935e51dd6
A27: Beton vægelementer, 20 cm tyk væg med 5-15 kg armering (11% udsparinger) | C27: b0eb3872-681f-4926-a6ff-a4abb949df65
A28: Betonmursten | B28: Tabel 7 2025: Concrete masonry brick | C28: 386839f2-2395-4837-bed2-ac3f1bf6ffbd
A29: Betonrør, armeret | B29: Tabel 7 2025: Concrete pipe, reinforced | C29: 387e876c-20b8-44e1-abba-b462808b2856
A30: Betonrør, u-armeret | C30: 93e404e4-575c-45e9-bbb6-9d8892aa9772
A31: Betonrør, u-armeret | B31: Tabel 7 2025: Concrete pipe, non-reinforced | C31: 4380000d-b6c7-4ed2-a535-b844bedb16d8
A32: Betontrappe, etagehøj | B32: Tabel 7 2025: Precast concrete part, stairs, (1,1 m wide, 9 steps each 16 cm) | C32: d1888fa1-9628-4fe9-a68e-43affab2990a
A33: Bindelag | B33: Tabel 7 2025: Asphalt binder | C33: 4e07bcc8-e145-4e9e-a99e-19a2b06e541a
A34: Bitumenemulsion (40% bitumen, 60% vand) | B34: Tabel 7 2025: Bitumen emulsion (40% bitumen, 60% water) | C34: aaf0ff53-267d-4a7c-8c83-f18f73164eb9
A35: Bitumenklæber | B35: Tabel 7 2025: Bitumen cold adhesive (60% bitumen, 23% solvent, 17% water) | C35: fa6c619d-f851-4c43-bb81-9f68639a26b4
A36: Blyplader | B36: Tabel 7 2025: Lead sheets | C36: 388b5a49-a64e-4d9b-b9a8-14d2be82b6ce
A37: Boksventilator 10.000 m3/h | B37: Tabel 7 2025: Ventilation centralized per 10000 m3/h | C37: 96e6fb26-af67-47e3-8660-10a8e841c52d
A38: Boksventilator 30.000 m3/h | B38: Tabel 7 2025: Ventilation centralized per 30000 m3/h | C38: 84c0bbfa-2b56-430f-b24c-03357082b00f
A39: Boksventilator 5.000 m3/h | B39: Tabel 7 2025: Ventilation centralized per 5000 m3/h | C39: d1bc982b-9e0e-4a24-9d8d-ed13362e7adc
A40: Bomuld | B40: Tabel 7 2025: Cotton, conventional | C40: 2fd013bd-def9-456d-b21f-0eef1ebc19f8
...
